Workbook

Sheet Читать_сначала
A1: Оценка выбросов АО «Невинномысский Азот» по заводам-аналогам (версия 13.10.2026)
A3: Ряд «Азота» — модельная оценка, а не отчётность предприятия. В тексте диссертации обозначается как оценка с указанием метода и интервала.
A4: Жёлтые ячейки — ввод (мощность «Азота», выбор сценария). Зелёные — результаты, считаются формулами.
A6: Листы:
A7: EPA_panel — 29 аммиачных заводов США, 2010–2023, прямые выбросы по газам и разделам отчётности (EPA GHGRP, файлы ghgp_data_20XX.xlsx, данные на 16.08.2024; ПГП по AR4).
A8: Аналоги — 19 интегрированных азотных комплексов (аммиак + азотная кислота, разделы G и V), полный ряд 2017–2023, процессный CO2 аммиака ≥ 150 тыс. т в 2023 г.
A9: Индексы — индексы к 2017 г. по каждому заводу и медиана/квартили по годам (формулы).
A10: Год_эффекты — медиана индексов с бутстреп-интервалом и годовые эффекты двусторонней модели с фиксированными эффектами (рассчитаны в Python, 2000 повторов, seed 2026).
A11: CF_мощности — удельные выбросы на тонну мощности по аммиаку для 5 комплексов CF Industries (мощность — форма 10-K за 2022 г.).
A12: Калибровка_CT — сравнение модельных оценок Climate TRACE с измеренными выбросами.
A13: Sluiskil_EU — европейский аналог Yara Sluiskil (PBL/TNO 2024), для сравнения динамики.
A14: Азот_оценка — уровень и ряд 2017–2023 для «Азота» в трёх сценариях мощности.
A16: Ограничения: (1) выпуск аммиака по заводам США в открытой отчётности не раскрывается, поэтому интенсивность считается на тонну мощности; (2) границы учёта CO2, связанного в карбамиде, в отчётности США и России могут различаться — сверить по методике 296-ФЗ; (3) динамика США отражает режим дешёвого газа без цены на углерод; для «Азота» она ближе, чем динамика ЕС, но не тождественна; (4) остановки «Азота» в 2025–2026 гг. в ряд 2017–2023 не входят.

Sheet EPA_panel
A1: Facility Id | B1: Название | C1: Штат | D1: Год | E1: Разделы | F1: Всего прямые, т CO2e | G1: CO2, т | H1: N2O, т CO2e | I1: Стац. сжигание (C) | J1: Аммиак, процесс (G) | K1: Азотная кислота (V) | L1: CO2 использован на месте | M1: CO2 передан
A2: 1000630 | B2: ADVANSIX INCORPORATED - HOPEWELL | C2: VA | D2: 2010 | E2: C,G,PP | F2: 1071582.2 | G2: 1070764 | H2: 521.202 | I2: 424333.2 | J2: 647249 | L2: N | M2: Y
A3: 1000630 | B3: ADVANSIX INCORPORATED - HOPEWELL | C3: VA | D3: 2011 | E3: C,G,PP | F3: 999354.42 | G3: 999002.6 | H3: 191.316 | I3: 340150.42 | J3: 659204 | L3: N | M3: Y
A4: 1000630 | B4: ADVANSIX INCORPORATED - HOPEWELL | C4: VA | D4: 2012 | E4: C,G,PP | F4: 1151345.4 | G4: 1150682 | H4: 390.38 | I4: 502156.38 | J4: 649189 | L4: N | M4: Y
A5: 1000630 | B5: ADVANSIX INCORPORATED - HOPEWELL | C5: VA | D5: 2013 | E5: C,G,PP | F5: 1115670.5 | G5: 1114892.8 | H5: 468.456 | I5: 470866.51 | J5: 644804 | L5: N | M5: Y
A6: 1000630 | B6: ADVANSIX INCORPORATED - HOPEWELL | C6: VA | D6: 2014 | E6: C,G,PP | F6: 1054912.6 | G6: 1054351.6 | H6: 330.78 | I6: 386319.63 | J6: 668593 | L6: N | M6: Y
A7: 1000630 | B7: ADVANSIX INCORPORATED - HOPEWELL | C7: VA | D7: 2015 | E7: C,G,PP | F7: 974277.29 | G7: 973824.7 | H7: 255.088 | I7: 359039.39 | J7: 615237.9 | L7: N | M7: Y
A8: 1000630 | B8: ADVANSIX INCORPORATED - HOPEWELL | C8: VA | D8: 2016 | E8: C,G,PP | F8: 958521.88 | G8: 958046.6 | H8: 271.776 | I8: 361952.88 | J8: 596569 | L8: N | M8: Y
A9: 1000630 | B9: ADVANSIX INCORPORATED - HOPEWELL | C9: VA | D9: 2017 | E9: C,G,PP | F9: 1040591.3 | G9: 1040131.5 | H9: 254.79 | I9: 416145.29 | J9: 624446 | L9: N | M9: Y
A10: 1000630 | B10: ADVANSIX INCORPORATED - HOPEWELL | C10: VA | D10: 2018 | E10: C,G,PP | F10: 995690.3 | G10: 995293 | H10: 216.05 | I10: 385473.3 | J10: 610217 | L10: N | M10: Y
A11: 1000630 | B11: ADVANSIX INCORPORATED - HOPEWELL | C11: VA | D11: 2019 | E11: C,G,PP | F11: 1241380.1 | G11: 1240822.2 | H11: 303.364 | I11: 541178.46 | J11: 700201.6 | L11: N | M11: Y
A12: 1000630 | B12: ADVANSIX INCORPORATED - HOPEWELL | C12: VA | D12: 2020 | E12: C,G,PP | F12: 1181515.8 | G12: 1180950.8 | H12: 307.238 | I12: 547761.39 | J12: 633754.4 | L12: N | M12: Y
A13: 1000630 | B13: ADVANSIX INCORPORATED - HOPEWELL | C13: VA | D13: 2021 | E13: C,G,PP | F13: 1206917.8 | G13: 1206346.8 | H13: 310.516 | I13: 553882.12 | J13: 653035.7 | L13: N | M13: Y
... A15: 1000630 | B15: ADVANSIX INCORPORATED - HOPEWELL | C15: VA | D15: 2023 | E15: C,G,PP | F15: 1227774.4 | G15: 1227197.4 | H15: 313.794 | I15: 559479.74 | J15: 668294.7 | L15: N | M15: Y
A16: 1002170 | B16: COFFEYVILLE RESOURCES NITROGEN FERT. | C16: KS | D16: 2010 | E16: C,G,V | F16: 1234377.7 | G16: 1086122.5 | H16: 148252.91 | I16: 4227.232 | J16: 1081900.2 | K16: 148250.23 | L16: Y | M16: N
A17: 1002170 | B17: COFFEYVILLE RESOURCES NITROGEN FERT. | C17: KS | D17: 2011 | E17: C,G,V | F17: 1528733.7 | G17: 1357660 | H17: 171071.97 | I17: 3620.636 | J17: 1354043.2 | K17: 171069.88 | L17: Y | M17: N
A18: 1002170 | B18: COFFEYVILLE RESOURCES NITROGEN FERT. | C18: KS | D18: 2012 | E18: C,G,V | F18: 1531472.1 | G18: 1277279.8 | H18: 254189.53 | I18: 5680.928 | J18: 1271604.9 | K18: 254186.25 | L18: Y | M18: N
A19: 1002170 | B19: COFFEYVILLE RESOURCES NITROGEN FERT. | C19: KS | D19: 2013 | E19: C,G,PP,V | F19: 1913140.3 | G19: 1353241.1 | H19: 559879.72 | I19: 41655.544 | J19: 1311628.3 | K19: 559856.47 | L19: Y | M19: Y
A20: 1002170 | B20: COFFEYVILLE RESOURCES NITROGEN FERT. | C20: KS | D20: 2014 | E20: C,G,PP,V | F20: 1986358.9 | G20: 1378551.2 | H20: 607784.41 | I20: 49271.364 | J20: 1329330.8 | K20: 607756.7 | L20: Y | M20: Y
A21: 1002170 | B21: COFFEYVILLE RESOURCES NITROGEN FERT. | C21: KS | D21: 2015 | E21: C,G,PP,V | F21: 1798429.1 | G21: 1281752.6 | H21: 516651.54 | I21: 53080.2 | J21: 1228727.2 | K21: 516621.74 | L21: Y | M21: Y
A22: 1002170 | B22: COFFEYVILLE RESOURCES NITROGEN FERT. | C22: KS | D22: 2016 | E22: C,G,PP,V | F22: 2111064.2 | G22: 1411929.1 | H22: 699111.87 | I22: 49227.164 | J22: 1362752.9 | K22: 699084.16 | L22: Y | M22: Y
A23: 1002170 | B23: COFFEYVILLE RESOURCES NITROGEN FERT. | C23: KS | D23: 2017 | E23: C,G,PP,V | F23: 2065938 | G23: 1342328.1 | H23: 723585.12 | I23: 52489.652 | J23: 1289892.7 | K23: 723555.62 | L23: Y | M23: Y
A24: 1002170 | B24: COFFEYVILLE RESOURCES NITROGEN FERT. | C24: KS | D24: 2018 | E24: C,G,PP,V | F24: 1973467.7 | G24: 1260937.6 | H24: 712506.08 | I24: 51197.708 | J24: 1209792.5 | K24: 712477.47 | L24: Y | M24: Y
A25: 1002170 | B25: COFFEYVILLE RESOURCES NITROGEN FERT. | C25: KS | D25: 2019 | E25: C,G,PP,V | F25: 2085170.2 | G25: 1478071.4 | H25: 607074.57 | I25: 51666.156 | J25: 1426458.4 | K25: 607045.67 | L25: Y | M25: Y
A26: 1002170 | B26: COFFEYVILLE RESOURCES NITROGEN FERT. | C26: KS | D26: 2020 | E26: C,G,PP,V | F26: 1689228.6 | G26: 1451330.3 | H26: 237875.52 | I26: 48580.668 | J26: 1402799.5 | K26: 237848.4 | L26: Y | M26: Y
A27: 1002170 | B27: COFFEYVILLE RESOURCES NITROGEN FERT. | C27: KS | D27: 2021 | E27: C,G,PP,V | F27: 1674019.8 | G27: 1423149.6 | H27: 250848.95 | I27: 44943.88 | J27: 1378252.3 | K27: 250823.62 | L27: Y | M27: Y
... A71: 1002301 | B71: CF INDUSTRIES NITROGEN, LLC - DONALDSONVILLE NITROGEN COMPLEX | C71: LA | D71: 2023 | E71: C,G,V | F71: 9475265.7 | G71: 7752761.9 | H71: 1721136.8 | I71: 2893094.1 | J71: 4862676.5 | K71: 1719495.2 | L71: Y | M71: N
A72: 1002380 | B72: AGRIUM US BORGER NITROGEN OPERATIONS | C72: TX | D72: 2010 | E72: C,G,PP | F72: 841955.43 | G72: 841593 | H72: 196.68 | I72: 351717.43 | J72: 490238 | L72: Y | M72: Y
A73: 1002380 | B73: AGRIUM US BORGER NITROGEN OPERATIONS | C73: TX | D73: 2011 | E73: C,G,PP | F73: 960401.74 | G73: 959974.8 | H73: 232.44 | I73: 413072.74 | J73: 547329 | L73: N | M73: Y
A74: 1002380 | B74: AGRIUM US BORGER NITROGEN OPERATIONS | C74: TX | D74: 2012 | E74: C,G,PP | F74: 986925.66 | G74: 986476 | H74: 252.406 | I74: 418717.66 | J74: 568208 | L74: Y | M74: Y
A75: 1002380 | B75: AGRIUM US BORGER NITROGEN OPERATIONS | C75: TX | D75: 2013 | E75: C,G,PP | F75: 888228.9 | G75: 887648.2 | H75: 372.202 | I75: 399855.9 | J75: 488373 | L75: Y | M75: Y
A76: 1002380 | B76: AGRIUM US BORGER NITROGEN OPERATIONS | C76: TX | D76: 2014 | E76: C,G,PP | F76: 921696.59 | G76: 921283.4 | H76: 224.692 | I76: 400481.49 | J76: 521215.1 | L76: Y | M76: Y
A77: 1002380 | B77: AGRIUM US BORGER NITROGEN OPERATIONS | C77: TX | D77: 2015 | E77: C,G,PP | F77: 828959.47 | G77: 828581.9 | H77: 205.322 | I77: 366010.07 | J77: 462949.4 | L77: Y | M77: Y
A78: 1002380 | B78: AGRIUM US BORGER NITROGEN OPERATIONS | C78: TX | D78: 2016 | E78: C,G,PP | F78: 747135.88 | G78: 746665.7 | H78: 255.684 | I78: 455768.88 | J78: 291367 | L78: Y | M78: Y
A79: 1002380 | B79: AGRIUM US BORGER NITROGEN OPERATIONS | C79: TX | D79: 2017 | E79: C,G,PP | F79: 852522.16 | G79: 852058 | H79: 252.406 | I79: 450002.06 | J79: 402520.1 | L79: Y | M79: Y
A80: 1002380 | B80: AGRIUM US BORGER NITROGEN OPERATIONS | C80: TX | D80: 2018 | E80: C,G,PP | F80: 1232578.8 | G80: 1232107.5 | H80: 256.28 | I80: 456955.88 | J80: 775622.9 | L80: Y | M80: Y
A81: 1002380 | B81: AGRIUM US BORGER NITROGEN OPERATIONS | C81: TX | D81: 2019 | E81: C,G,PP | F81: 902306.71 | G81: 901885.3 | H81: 229.162 | I81: 408678.31 | J81: 493628.4 | L81: Y | M81: Y
A82: 1002380 | B82: AGRIUM US BORGER NITROGEN OPERATIONS | C82: TX | D82: 2020 | E82: C,G,PP | F82: 955607.87 | G82: 955161.8 | H82: 242.572 | I82: 432219.47 | J82: 523388.4 | L82: Y | M82: Y
A83: 1002380 | B83: AGRIUM US BORGER NITROGEN OPERATIONS | C83: TX | D83: 2021 | E83: C,G,PP | F83: 730767.12 | G83: 730390.1 | H83: 205.024 | I83: 365381.62 | J83: 365385.5 | L83: Y | M83: Y
... A85: 1002380 | B85: AGRIUM US BORGER NITROGEN OPERATIONS | C85: TX | D85: 2023 | E85: C,G,PP | F85: 736027.6 | G85: 735656.6 | H85: 201.746 | I85: 359979.5 | J85: 376048.1 | L85: Y | M85: Y
...

Sheet Аналоги
A1: Facility Id | B1: Название | C1: Процессный CO2 аммиака 2023, т | D1: N2O / процессный CO2, 2023 | E1: Сжигание / процессный CO2, 2023
A2: 1002301 | B2: CF INDUSTRIES NITROGEN, LLC - DONALDSONVILLE NITROGEN COMPLEX | C2: 4862676.5 | D2: =IFERROR(SUMIFS(EPA_panel!K:K,EPA_panel!A:A,A2,EPA_panel!D:D,2023)/C2,0) -> 0.35361085 | E2: =SUMIFS(EPA_panel!I:I,EPA_panel!A:A,A2,EPA_panel!D:D,2023)/C2 -> 0.59495919
A3: 1006005 | B3: CF Industries Nitrogen, LLC-Port Neal Nitrogen Complex | C3: 1624172.7 | D3: =IFERROR(SUMIFS(EPA_panel!K:K,EPA_panel!A:A,A3,EPA_panel!D:D,2023)/C3,0) -> 0.36380096 | E3: =SUMIFS(EPA_panel!I:I,EPA_panel!A:A,A3,EPA_panel!D:D,2023)/C3 -> 0.60103723
A4: 1002170 | B4: COFFEYVILLE RESOURCES NITROGEN FERT. | C4: 1352802.2 | D4: =IFERROR(SUMIFS(EPA_panel!K:K,EPA_panel!A:A,A4,EPA_panel!D:D,2023)/C4,0) -> 0.17705352 | E4: =SUMIFS(EPA_panel!I:I,EPA_panel!A:A,A4,EPA_panel!D:D,2023)/C4 -> 0.035973046
A5: 1002407 | B5: KOCH FERITLIZER ENID LLC ENID NITROGEN PLT | C5: 1348509.2 | D5: =IFERROR(SUMIFS(EPA_panel!K:K,EPA_panel!A:A,A5,EPA_panel!D:D,2023)/C5,0) -> 0.00010673565 | E5: =SUMIFS(EPA_panel!I:I,EPA_panel!A:A,A5,EPA_panel!D:D,2023)/C5 -> 0.7647767
A6: 1002275 | B6: VERDIGRIS PLT | C6: 1176114 | D6: =IFERROR(SUMIFS(EPA_panel!K:K,EPA_panel!A:A,A6,EPA_panel!D:D,2023)/C6,0) -> 1.0602666 | E6: =SUMIFS(EPA_panel!I:I,EPA_panel!A:A,A6,EPA_panel!D:D,2023)/C6 -> 0.79206105
A7: 1004340 | B7: PCS NITROGEN FERTILIZER, L.P. | C7: 1126460.7 | D7: =IFERROR(SUMIFS(EPA_panel!K:K,EPA_panel!A:A,A7,EPA_panel!D:D,2023)/C7,0) -> 0.051715452 | E7: =SUMIFS(EPA_panel!I:I,EPA_panel!A:A,A7,EPA_panel!D:D,2023)/C7 -> 0.33910308
A8: 1012918 | B8: Iowa Fertilizer Company | C8: 1048097.7 | D8: =IFERROR(SUMIFS(EPA_panel!K:K,EPA_panel!A:A,A8,EPA_panel!D:D,2023)/C8,0) -> 0.00034801336 | E8: =SUMIFS(EPA_panel!I:I,EPA_panel!A:A,A8,EPA_panel!D:D,2023)/C8 -> 0.28776159
A9: 1002229 | B9: PCS Nitrogen Ohio, L.P. | C9: 872546.4 | D9: =IFERROR(SUMIFS(EPA_panel!K:K,EPA_panel!A:A,A9,EPA_panel!D:D,2023)/C9,0) -> 0.00017110609 | E9: =SUMIFS(EPA_panel!I:I,EPA_panel!A:A,A9,EPA_panel!D:D,2023)/C9 -> 0.5706047
A10: 1004183 | B10: CF Industries Nitrogen, LLC - Yazoo City Facility | C10: 708631.5 | D10: =IFERROR(SUMIFS(EPA_panel!K:K,EPA_panel!A:A,A10,EPA_panel!D:D,2023)/C10,0) -> 1.8317981 | E10: =SUMIFS(EPA_panel!I:I,EPA_panel!A:A,A10,EPA_panel!D:D,2023)/C10 -> 0.60287384
A11: 1003993 | B11: EL DORADO CHEMICAL COMPANY | C11: 521423.3 | D11: =IFERROR(SUMIFS(EPA_panel!K:K,EPA_panel!A:A,A11,EPA_panel!D:D,2023)/C11,0) -> 0.17884345 | E11: =SUMIFS(EPA_panel!I:I,EPA_panel!A:A,A11,EPA_panel!D:D,2023)/C11 -> 0.79224546
A12: 1003489 | B12: PCS NITROGEN FERTILIZER LP - GEISMAR AGRICULTURAL NITROGEN & PHOSPHATE PLANT | C12: 515726.2 | D12: =IFERROR(SUMIFS(EPA_panel!K:K,EPA_panel!A:A,A12,EPA_panel!D:D,2023)/C12,0) -> 1.5266417 | E12: =SUMIFS(EPA_panel!I:I,EPA_panel!A:A,A12,EPA_panel!D:D,2023)/C12 -> 0.70393143
A13: 1005788 | B13: TERRA INTERNATIONAL (OKLAHOMA) LLC | C13: 509521.6 | D13: =IFERROR(SUMIFS(EPA_panel!K:K,EPA_panel!A:A,A13,EPA_panel!D:D,2023)/C13,0) -> 0.64432063 | E13: =SUMIFS(EPA_panel!I:I,EPA_panel!A:A,A13,EPA_panel!D:D,2023)/C13 -> 0.69218414
... A20: 1005924 | B20: Cheyenne Plant | C20: 170040 | D20: =IFERROR(SUMIFS(EPA_panel!K:K,EPA_panel!A:A,A20,EPA_panel!D:D,2023)/C20,0) -> 0.38217221 | E20: =SUMIFS(EPA_panel!I:I,EPA_panel!A:A,A20,EPA_panel!D:D,2023)/C20 -> 0.87456916
B22: Q25 | D22: =QUARTILE(D2:D20,1) -> 0.10218515 | E22: =QUARTILE(E2:E20,1) -> 0.57963277
B23: Медиана | D23: =MEDIAN(D2:D20) -> 0.35361085 | E23: =MEDIAN(E2:E20) -> 0.6127851
B24: Q75 | D24: =QUARTILE(D2:D20,3) -> 0.60832454 | E24: =QUARTILE(E2:E20,3) -> 0.73435407
B26: Критерии отбора: разделы G и V в 2023 г.; данные за каждый год 2017–2023; процессный CO2 аммиака ≥ 150 тыс. т в 2023 г.

Sheet Индексы
A1: Всего прямые выбросы, т CO2e
A2: Facility Id | B2: Название | C2: 2017 | D2: 2018 | E2: 2019 | F2: 2020 | G2: 2021 | H2: 2022 | I2: 2023 | K2: I 2017 | L2: I 2018 | M2: I 2019 | N2: I 2020 | O2: I 2021 | P2: I 2022 | Q2: I 2023
A3: 1002301 | B3: CF INDUSTRIES NITROGEN, LLC - DONALDSONVILLE NITROGEN COMPLEX | C3: =SUMIFS(EPA_panel!F:F,EPA_panel!A:A,$A3,EPA_panel!D:D,2017) -> 8730636.2 | D3: =SUMIFS(EPA_panel!F:F,EPA_panel!A:A,$A3,EPA_panel!D:D,2018) -> 8685862 | E3: =SUMIFS(EPA_panel!F:F,EPA_panel!A:A,$A3,EPA_panel!D:D,2019) -> 10005456 | F3: =SUMIFS(EPA_panel!F:F,EPA_panel!A:A,$A3,EPA_panel!D:D,2020) -> 9236777.7 | G3: =SUMIFS(EPA_panel!F:F,EPA_panel!A:A,$A3,EPA_panel!D:D,2021) -> 9052754.3 | H3: =SUMIFS(EPA_panel!F:F,EPA_panel!A:A,$A3,EPA_panel!D:D,2022) -> 9155496.1 | I3: =SUMIFS(EPA_panel!F:F,EPA_panel!A:A,$A3,EPA_panel!D:D,2023) -> 9475265.7 | K3: =IF($C3=0,"",C3/$C3) -> 1 | L3: =IF($C3=0,"",D3/$C3) -> 0.99487161 | M3: =IF($C3=0,"",E3/$C3) -> 1.1460169 | N3: =IF($C3=0,"",F3/$C3) -> 1.057973 | O3: =IF($C3=0,"",G3/$C3) -> 1.0368951 | P3: =IF($C3=0,"",H3/$C3) -> 1.0486631 | Q3: =IF($C3=0,"",I3/$C3) -> 1.0852893
A4: 1006005 | B4: CF Industries Nitrogen, LLC-Port Neal Nitrogen Complex | C4: =SUMIFS(EPA_panel!F:F,EPA_panel!A:A,$A4,EPA_panel!D:D,2017) -> 2786006.2 | D4: =SUMIFS(EPA_panel!F:F,EPA_panel!A:A,$A4,EPA_panel!D:D,2018) -> 3027856.1 | E4: =SUMIFS(EPA_panel!F:F,EPA_panel!A:A,$A4,EPA_panel!D:D,2019) -> 3004988 | F4: =SUMIFS(EPA_panel!F:F,EPA_panel!A:A,$A4,EPA_panel!D:D,2020) -> 2888938.6 | G4: =SUMIFS(EPA_panel!F:F,EPA_panel!A:A,$A4,EPA_panel!D:D,2021) -> 2764238 | H4: =SUMIFS(EPA_panel!F:F,EPA_panel!A:A,$A4,EPA_panel!D:D,2022) -> 3180457.4 | I4: =SUMIFS(EPA_panel!F:F,EPA_panel!A:A,$A4,EPA_panel!D:D,2023) -> 3191236.6 | K4: =IF($C4=0,"",C4/$C4) -> 1 | L4: =IF($C4=0,"",D4/$C4) -> 1.0868088 | M4: =IF($C4=0,"",E4/$C4) -> 1.0786006 | N4: =IF($C4=0,"",F4/$C4) -> 1.0369462 | O4: =IF($C4=0,"",G4/$C4) -> 0.99218657 | P4: =IF($C4=0,"",H4/$C4) -> 1.141583 | Q4: =IF($C4=0,"",I4/$C4) -> 1.1454521
A5: 1002170 | B5: COFFEYVILLE RESOURCES NITROGEN FERT. | C5: =SUMIFS(EPA_panel!F:F,EPA_panel!A:A,$A5,EPA_panel!D:D,2017) -> 2065938 | D5: =SUMIFS(EPA_panel!F:F,EPA_panel!A:A,$A5,EPA_panel!D:D,2018) -> 1973467.7 | E5: =SUMIFS(EPA_panel!F:F,EPA_panel!A:A,$A5,EPA_panel!D:D,2019) -> 2085170.2 | F5: =SUMIFS(EPA_panel!F:F,EPA_panel!A:A,$A5,EPA_panel!D:D,2020) -> 1689228.6 | G5: =SUMIFS(EPA_panel!F:F,EPA_panel!A:A,$A5,EPA_panel!D:D,2021) -> 1674019.8 | H5: =SUMIFS(EPA_panel!F:F,EPA_panel!A:A,$A5,EPA_panel!D:D,2022) -> 1481142.5 | I5: =SUMIFS(EPA_panel!F:F,EPA_panel!A:A,$A5,EPA_panel!D:D,2023) -> 1640985 | K5: =IF($C5=0,"",C5/$C5) -> 1 | L5: =IF($C5=0,"",D5/$C5) -> 0.95524053 | M5: =IF($C5=0,"",E5/$C5) -> 1.0093092 | N5: =IF($C5=0,"",F5/$C5) -> 0.81765696 | O5: =IF($C5=0,"",G5/$C5) -> 0.81029529 | P5: =IF($C5=0,"",H5/$C5) -> 0.71693466 | Q5: =IF($C5=0,"",I5/$C5) -> 0.79430507
A6: 1002407 | B6: KOCH FERITLIZER ENID LLC ENID NITROGEN PLT | C6: =SUMIFS(EPA_panel!F:F,EPA_panel!A:A,$A6,EPA_panel!D:D,2017) -> 1672354.4 | D6: =SUMIFS(EPA_panel!F:F,EPA_panel!A:A,$A6,EPA_panel!D:D,2018) -> 1845963.2 | E6: =SUMIFS(EPA_panel!F:F,EPA_panel!A:A,$A6,EPA_panel!D:D,2019) -> 2204568.8 | F6: =SUMIFS(EPA_panel!F:F,EPA_panel!A:A,$A6,EPA_panel!D:D,2020) -> 2359236.2 | G6: =SUMIFS(EPA_panel!F:F,EPA_panel!A:A,$A6,EPA_panel!D:D,2021) -> 2123972.5 | H6: =SUMIFS(EPA_panel!F:F,EPA_panel!A:A,$A6,EPA_panel!D:D,2022) -> 2288147.7 | I6: =SUMIFS(EPA_panel!F:F,EPA_panel!A:A,$A6,EPA_panel!D:D,2023) -> 2379961.5 | K6: =IF($C6=0,"",C6/$C6) -> 1 | L6: =IF($C6=0,"",D6/$C6) -> 1.103811 | M6: =IF($C6=0,"",E6/$C6) -> 1.3182426 | N6: =IF($C6=0,"",F6/$C6) -> 1.4107274 | O6: =IF($C6=0,"",G6/$C6) -> 1.2700493 | P6: =IF($C6=0,"",H6/$C6) -> 1.3682194 | Q6: =IF($C6=0,"",I6/$C6) -> 1.4231203
A7: 1002275 | B7: VERDIGRIS PLT | C7: =SUMIFS(EPA_panel!F:F,EPA_panel!A:A,$A7,EPA_panel!D:D,2017) -> 3970697 | D7: =SUMIFS(EPA_panel!F:F,EPA_panel!A:A,$A7,EPA_panel!D:D,2018) -> 3869564.4 | E7: =SUMIFS(EPA_panel!F:F,EPA_panel!A:A,$A7,EPA_panel!D:D,2019) -> 3564162.9 | F7: =SUMIFS(EPA_panel!F:F,EPA_panel!A:A,$A7,EPA_panel!D:D,2020) -> 3776285.1 | G7: =SUMIFS(EPA_panel!F:F,EPA_panel!A:A,$A7,EPA_panel!D:D,2021) -> 2808146.3 | H7: =SUMIFS(EPA_panel!F:F,EPA_panel!A:A,$A7,EPA_panel!D:D,2022) -> 3698601.7 | I7: =SUMIFS(EPA_panel!F:F,EPA_panel!A:A,$A7,EPA_panel!D:D,2023) -> 3354662.5 | K7: =IF($C7=0,"",C7/$C7) -> 1 | L7: =IF($C7=0,"",D7/$C7) -> 0.97453026 | M7: =IF($C7=0,"",E7/$C7) -> 0.89761645 | N7: =IF($C7=0,"",F7/$C7) -> 0.95103834 | O7: =IF($C7=0,"",G7/$C7) -> 0.70721749 | P7: =IF($C7=0,"",H7/$C7) -> 0.93147417 | Q7: =IF($C7=0,"",I7/$C7) -> 0.84485483
A8: 1004340 | B8: PCS NITROGEN FERTILIZER, L.P. | C8: =SUMIFS(EPA_panel!F:F,EPA_panel!A:A,$A8,EPA_panel!D:D,2017) -> 1785426.3 | D8: =SUMIFS(EPA_panel!F:F,EPA_panel!A:A,$A8,EPA_panel!D:D,2018) -> 1808477.7 | E8: =SUMIFS(EPA_panel!F:F,EPA_panel!A:A,$A8,EPA_panel!D:D,2019) -> 1695111.5 | F8: =SUMIFS(EPA_panel!F:F,EPA_panel!A:A,$A8,EPA_panel!D:D,2020) -> 1732541.7 | G8: =SUMIFS(EPA_panel!F:F,EPA_panel!A:A,$A8,EPA_panel!D:D,2021) -> 1877928.3 | H8: =SUMIFS(EPA_panel!F:F,EPA_panel!A:A,$A8,EPA_panel!D:D,2022) -> 1250737.8 | I8: =SUMIFS(EPA_panel!F:F,EPA_panel!A:A,$A8,EPA_panel!D:D,2023) -> 1566702.4 | K8: =IF($C8=0,"",C8/$C8) -> 1 | L8: =IF($C8=0,"",D8/$C8) -> 1.0129109 | M8: =IF($C8=0,"",E8/$C8) -> 0.94941556 | N8: =IF($C8=0,"",F8/$C8) -> 0.97037986 | O8: =IF($C8=0,"",G8/$C8) -> 1.0518095 | P8: =IF($C8=0,"",H8/$C8) -> 0.70052613 | Q8: =IF($C8=0,"",I8/$C8) -> 0.87749489
A9: 1012918 | B9: Iowa Fertilizer Company | C9: =SUMIFS(EPA_panel!F:F,EPA_panel!A:A,$A9,EPA_panel!D:D,2017) -> 1040649.4 | D9: =SUMIFS(EPA_panel!F:F,EPA_panel!A:A,$A9,EPA_panel!D:D,2018) -> 1684329.4 | E9: =SUMIFS(EPA_panel!F:F,EPA_panel!A:A,$A9,EPA_panel!D:D,2019) -> 1706459.9 | F9: =SUMIFS(EPA_panel!F:F,EPA_panel!A:A,$A9,EPA_panel!D:D,2020) -> 1866658.7 | G9: =SUMIFS(EPA_panel!F:F,EPA_panel!A:A,$A9,EPA_panel!D:D,2021) -> 1473227.6 | H9: =SUMIFS(EPA_panel!F:F,EPA_panel!A:A,$A9,EPA_panel!D:D,2022) -> 1593663 | I9: =SUMIFS(EPA_panel!F:F,EPA_panel!A:A,$A9,EPA_panel!D:D,2023) -> 1350064.7 | K9: =IF($C9=0,"",C9/$C9) -> 1 | L9: =IF($C9=0,"",D9/$C9) -> 1.6185368 | M9: =IF($C9=0,"",E9/$C9) -> 1.6398029 | N9: =IF($C9=0,"",F9/$C9) -> 1.7937441 | O9: =IF($C9=0,"",G9/$C9) -> 1.415681 | P9: =IF($C9=0,"",H9/$C9) -> 1.531412 | Q9: =IF($C9=0,"",I9/$C9) -> 1.2973291
A10: 1002229 | B10: PCS Nitrogen Ohio, L.P. | C10: =SUMIFS(EPA_panel!F:F,EPA_panel!A:A,$A10,EPA_panel!D:D,2017) -> 1509004.3 | D10: =SUMIFS(EPA_panel!F:F,EPA_panel!A:A,$A10,EPA_panel!D:D,2018) -> 1622211.5 | E10: =SUMIFS(EPA_panel!F:F,EPA_panel!A:A,$A10,EPA_panel!D:D,2019) -> 1502337.5 | F10: =SUMIFS(EPA_panel!F:F,EPA_panel!A:A,$A10,EPA_panel!D:D,2020) -> 1416352.1 | G10: =SUMIFS(EPA_panel!F:F,EPA_panel!A:A,$A10,EPA_panel!D:D,2021) -> 1730840.7 | H10: =SUMIFS(EPA_panel!F:F,EPA_panel!A:A,$A10,EPA_panel!D:D,2022) -> 1541265 | I10: =SUMIFS(EPA_panel!F:F,EPA_panel!A:A,$A10,EPA_panel!D:D,2023) -> 1370574.8 | K10: =IF($C10=0,"",C10/$C10) -> 1 | L10: =IF($C10=0,"",D10/$C10) -> 1.0750211 | M10: =IF($C10=0,"",E10/$C10) -> 0.99558194 | N10: =IF($C10=0,"",F10/$C10) -> 0.93860039 | O10: =IF($C10=0,"",G10/$C10) -> 1.1470084 | P10: =IF($C10=0,"",H10/$C10) -> 1.0213787 | Q10: =IF($C10=0,"",I10/$C10) -> 0.9082643
A11: 1004183 | B11: CF Industries Nitrogen, LLC - Yazoo City Facility | C11: =SUMIFS(EPA_panel!F:F,EPA_panel!A:A,$A11,EPA_panel!D:D,2017) -> 2445427.8 | D11: =SUMIFS(EPA_panel!F:F,EPA_panel!A:A,$A11,EPA_panel!D:D,2018) -> 2124413 | E11: =SUMIFS(EPA_panel!F:F,EPA_panel!A:A,$A11,EPA_panel!D:D,2019) -> 2393123 | F11: =SUMIFS(EPA_panel!F:F,EPA_panel!A:A,$A11,EPA_panel!D:D,2020) -> 2423738.1 | G11: =SUMIFS(EPA_panel!F:F,EPA_panel!A:A,$A11,EPA_panel!D:D,2021) -> 2090197.2 | H11: =SUMIFS(EPA_panel!F:F,EPA_panel!A:A,$A11,EPA_panel!D:D,2022) -> 2454971 | I11: =SUMIFS(EPA_panel!F:F,EPA_panel!A:A,$A11,EPA_panel!D:D,2023) -> 2433916.7 | K11: =IF($C11=0,"",C11/$C11) -> 1 | L11: =IF($C11=0,"",D11/$C11) -> 0.86872858 | M11: =IF($C11=0,"",E11/$C11) -> 0.97861119 | N11: =IF($C11=0,"",F11/$C11) -> 0.99113052 | O11: =IF($C11=0,"",G11/$C11) -> 0.85473685 | P11: =IF($C11=0,"",H11/$C11) -> 1.0039025 | Q11: =IF($C11=0,"",I11/$C11) -> 0.99529283
A12: 1003993 | B12: EL DORADO CHEMICAL COMPANY | C12: =SUMIFS(EPA_panel!F:F,EPA_panel!A:A,$A12,EPA_panel!D:D,2017) -> 1006988.3 | D12: =SUMIFS(EPA_panel!F:F,EPA_panel!A:A,$A12,EPA_panel!D:D,2018) -> 1113481.6 | E12: =SUMIFS(EPA_panel!F:F,EPA_panel!A:A,$A12,EPA_panel!D:D,2019) -> 890953.43 | F12: =SUMIFS(EPA_panel!F:F,EPA_panel!A:A,$A12,EPA_panel!D:D,2020) -> 931867.73 | G12: =SUMIFS(EPA_panel!F:F,EPA_panel!A:A,$A12,EPA_panel!D:D,2021) -> 951491.91 | H12: =SUMIFS(EPA_panel!F:F,EPA_panel!A:A,$A12,EPA_panel!D:D,2022) -> 911786.54 | I12: =SUMIFS(EPA_panel!F:F,EPA_panel!A:A,$A12,EPA_panel!D:D,2023) -> 1027771.7 | K12: =IF($C12=0,"",C12/$C12) -> 1 | L12: =IF($C12=0,"",D12/$C12) -> 1.1057543 | M12: =IF($C12=0,"",E12/$C12) -> 0.88477041 | N12: =IF($C12=0,"",F12/$C12) -> 0.92540077 | O12: =IF($C12=0,"",G12/$C12) -> 0.94488877 | P12: =IF($C12=0,"",H12/$C12) -> 0.90545894 | Q12: =IF($C12=0,"",I12/$C12) -> 1.0206392
A13: 1003489 | B13: PCS NITROGEN FERTILIZER LP - GEISMAR AGRICULTURAL NITROGEN & PHOSPHATE PLANT | C13: =SUMIFS(EPA_panel!F:F,EPA_panel!A:A,$A13,EPA_panel!D:D,2017) -> 1244129.5 | D13: =SUMIFS(EPA_panel!F:F,EPA_panel!A:A,$A13,EPA_panel!D:D,2018) -> 1230111.4 | E13: =SUMIFS(EPA_panel!F:F,EPA_panel!A:A,$A13,EPA_panel!D:D,2019) -> 1428934.2 | F13: =SUMIFS(EPA_panel!F:F,EPA_panel!A:A,$A13,EPA_panel!D:D,2020) -> 1491749.3 | G13: =SUMIFS(EPA_panel!F:F,EPA_panel!A:A,$A13,EPA_panel!D:D,2021) -> 1458822.9 | H13: =SUMIFS(EPA_panel!F:F,EPA_panel!A:A,$A13,EPA_panel!D:D,2022) -> 1543456.3 | I13: =SUMIFS(EPA_panel!F:F,EPA_panel!A:A,$A13,EPA_panel!D:D,2023) -> 1666091.2 | K13: =IF($C13=0,"",C13/$C13) -> 1 | L13: =IF($C13=0,"",D13/$C13) -> 0.98873266 | M13: =IF($C13=0,"",E13/$C13) -> 1.1485414 | N13: =IF($C13=0,"",F13/$C13) -> 1.1990306 | O13: =IF($C13=0,"",G13/$C13) -> 1.1725651 | P13: =IF($C13=0,"",H13/$C13) -> 1.2405913 | Q13: =IF($C13=0,"",I13/$C13) -> 1.3391622
A14: 1005788 | B14: TERRA INTERNATIONAL (OKLAHOMA) LLC | C14: =SUMIFS(EPA_panel!F:F,EPA_panel!A:A,$A14,EPA_panel!D:D,2017) -> 1193834.4 | D14: =SUMIFS(EPA_panel!F:F,EPA_panel!A:A,$A14,EPA_panel!D:D,2018) -> 1324696.7 | E14: =SUMIFS(EPA_panel!F:F,EPA_panel!A:A,$A14,EPA_panel!D:D,2019) -> 1098808.2 | F14: =SUMIFS(EPA_panel!F:F,EPA_panel!A:A,$A14,EPA_panel!D:D,2020) -> 1277183.7 | G14: =SUMIFS(EPA_panel!F:F,EPA_panel!A:A,$A14,EPA_panel!D:D,2021) -> 1246631.4 | H14: =SUMIFS(EPA_panel!F:F,EPA_panel!A:A,$A14,EPA_panel!D:D,2022) -> 1303743.3 | I14: =SUMIFS(EPA_panel!F:F,EPA_panel!A:A,$A14,EPA_panel!D:D,2023) -> 1190499.6 | K14: =IF($C14=0,"",C14/$C14) -> 1 | L14: =IF($C14=0,"",D14/$C14) -> 1.1096151 | M14: =IF($C14=0,"",E14/$C14) -> 0.92040249 | N14: =IF($C14=0,"",F14/$C14) -> 1.0698164 | O14: =IF($C14=0,"",G14/$C14) -> 1.0442247 | P14: =IF($C14=0,"",H14/$C14) -> 1.0920638 | Q14: =IF($C14=0,"",I14/$C14) -> 0.99720668
... A21: 1005924 | B21: Cheyenne Plant | C21: =SUMIFS(EPA_panel!F:F,EPA_panel!A:A,$A21,EPA_panel!D:D,2017) -> 398625.38 | D21: =SUMIFS(EPA_panel!F:F,EPA_panel!A:A,$A21,EPA_panel!D:D,2018) -> 406368.32 | E21: =SUMIFS(EPA_panel!F:F,EPA_panel!A:A,$A21,EPA_panel!D:D,2019) -> 434448.18 | F21: =SUMIFS(EPA_panel!F:F,EPA_panel!A:A,$A21,EPA_panel!D:D,2020) -> 432358.3 | G21: =SUMIFS(EPA_panel!F:F,EPA_panel!A:A,$A21,EPA_panel!D:D,2021) -> 452804.81 | H21: =SUMIFS(EPA_panel!F:F,EPA_panel!A:A,$A21,EPA_panel!D:D,2022) -> 509609.53 | I21: =SUMIFS(EPA_panel!F:F,EPA_panel!A:A,$A21,EPA_panel!D:D,2023) -> 383736.3 | K21: =IF($C21=0,"",C21/$C21) -> 1 | L21: =IF($C21=0,"",D21/$C21) -> 1.0194241 | M21: =IF($C21=0,"",E21/$C21) -> 1.0898658 | N21: =IF($C21=0,"",F21/$C21) -> 1.0846231 | O21: =IF($C21=0,"",G21/$C21) -> 1.1359157 | P21: =IF($C21=0,"",H21/$C21) -> 1.2784172 | Q21: =IF($C21=0,"",I21/$C21) -> 0.96264894
B22: Q25 | K22: =QUARTILE(K3:K21,1) -> 1 | L22: =QUARTILE(L3:L21,1) -> 0.97913507 | M22: =QUARTILE(M3:M21,1) -> 0.93490903 | N22: =QUARTILE(N3:N21,1) -> 0.9607091 | O22: =QUARTILE(O3:O21,1) -> 0.95410131 | P22: =QUARTILE(P3:P21,1) -> 0.9895563 | Q22: =QUARTILE(Q3:Q21,1) -> 0.97897089
B23: Медиана | K23: =MEDIAN(K3:K21) -> 1 | L23: =MEDIAN(L3:L21) -> 1.0194241 | M23: =MEDIAN(M3:M21) -> 0.99558194 | N23: =MEDIAN(N3:N21) -> 1.0569833 | O23: =MEDIAN(O3:O21) -> 1.0442247 | P23: =MEDIAN(P3:P21) -> 1.0486631 | Q23: =MEDIAN(Q3:Q21) -> 1.0281023
B24: Q75 | K24: =QUARTILE(K3:K21,3) -> 1 | L24: =QUARTILE(L3:L21,3) -> 1.1047826 | M24: =QUARTILE(M3:M21,3) -> 1.1179414 | N24: =QUARTILE(N3:N21,3) -> 1.1523906 | O24: =QUARTILE(O3:O21,3) -> 1.141462 | P24: =QUARTILE(P3:P21,3) -> 1.1910872 | Q24: =QUARTILE(Q3:Q21,3) -> 1.2268678
A27: CO2, т
A28: Facility Id | B28: Название | C28: 2017 | D28: 2018 | E28: 2019 | F28: 2020 | G28: 2021 | H28: 2022 | I28: 2023 | K28: I 2017 | L28: I 2018 | M28: I 2019 | N28: I 2020 | O28: I 2021 | P28: I 2022 | Q28: I 2023
A29: 1002301 | B29: CF INDUSTRIES NITROGEN, LLC - DONALDSONVILLE NITROGEN COMPLEX | C29: =SUMIFS(EPA_panel!G:G,EPA_panel!A:A,$A29,EPA_panel!D:D,2017) -> 7787715.1 | D29: =SUMIFS(EPA_panel!G:G,EPA_panel!A:A,$A29,EPA_panel!D:D,2018) -> 7484069.7 | E29: =SUMIFS(EPA_panel!G:G,EPA_panel!A:A,$A29,EPA_panel!D:D,2019) -> 8016286 | F29: =SUMIFS(EPA_panel!G:G,EPA_panel!A:A,$A29,EPA_panel!D:D,2020) -> 7649699.4 | G29: =SUMIFS(EPA_panel!G:G,EPA_panel!A:A,$A29,EPA_panel!D:D,2021) -> 7206879.8 | H29: =SUMIFS(EPA_panel!G:G,EPA_panel!A:A,$A29,EPA_panel!D:D,2022) -> 7827402 | I29: =SUMIFS(EPA_panel!G:G,EPA_panel!A:A,$A29,EPA_panel!D:D,2023) -> 7752761.9 | K29: =IF($C29=0,"",C29/$C29) -> 1 | L29: =IF($C29=0,"",D29/$C29) -> 0.96100969 | M29: =IF($C29=0,"",E29/$C29) -> 1.0293502 | N29: =IF($C29=0,"",F29/$C29) -> 0.98227777 | O29: =IF($C29=0,"",G29/$C29) -> 0.92541647 | P29: =IF($C29=0,"",H29/$C29) -> 1.0050961 | Q29: =IF($C29=0,"",I29/$C29) -> 0.99551175
A30: 1006005 | B30: CF Industries Nitrogen, LLC-Port Neal Nitrogen Complex | C30: =SUMIFS(EPA_panel!G:G,EPA_panel!A:A,$A30,EPA_panel!D:D,2017) -> 2343845.5 | D30: =SUMIFS(EPA_panel!G:G,EPA_panel!A:A,$A30,EPA_panel!D:D,2018) -> 2486125.8 | E30: =SUMIFS(EPA_panel!G:G,EPA_panel!A:A,$A30,EPA_panel!D:D,2019) -> 2432398.8 | F30: =SUMIFS(EPA_panel!G:G,EPA_panel!A:A,$A30,EPA_panel!D:D,2020) -> 2499053.3 | G30: =SUMIFS(EPA_panel!G:G,EPA_panel!A:A,$A30,EPA_panel!D:D,2021) -> 2223422 | H30: =SUMIFS(EPA_panel!G:G,EPA_panel!A:A,$A30,EPA_panel!D:D,2022) -> 2563756 | I30: =SUMIFS(EPA_panel!G:G,EPA_panel!A:A,$A30,EPA_panel!D:D,2023) -> 2599267.7 | K30: =IF($C30=0,"",C30/$C30) -> 1 | L30: =IF($C30=0,"",D30/$C30) -> 1.0607038 | M30: =IF($C30=0,"",E30/$C30) -> 1.0377812 | N30: =IF($C30=0,"",F30/$C30) -> 1.0662193 | O30: =IF($C30=0,"",G30/$C30) -> 0.9486214 | P30: =IF($C30=0,"",H30/$C30) -> 1.0938247 | Q30: =IF($C30=0,"",I30/$C30) -> 1.1089757
A31: 1002170 | B31: COFFEYVILLE RESOURCES NITROGEN FERT. | C31: =SUMIFS(EPA_panel!G:G,EPA_panel!A:A,$A31,EPA_panel!D:D,2017) -> 1342328.1 | D31: =SUMIFS(EPA_panel!G:G,EPA_panel!A:A,$A31,EPA_panel!D:D,2018) -> 1260937.6 | E31: =SUMIFS(EPA_panel!G:G,EPA_panel!A:A,$A31,EPA_panel!D:D,2019) -> 1478071.4 | F31: =SUMIFS(EPA_panel!G:G,EPA_panel!A:A,$A31,EPA_panel!D:D,2020) -> 1451330.3 | G31: =SUMIFS(EPA_panel!G:G,EPA_panel!A:A,$A31,EPA_panel!D:D,2021) -> 1423149.6 | H31: =SUMIFS(EPA_panel!G:G,EPA_panel!A:A,$A31,EPA_panel!D:D,2022) -> 1176218.5 | I31: =SUMIFS(EPA_panel!G:G,EPA_panel!A:A,$A31,EPA_panel!D:D,2023) -> 1401416.2 | K31: =IF($C31=0,"",C31/$C31) -> 1 | L31: =IF($C31=0,"",D31/$C31) -> 0.93936617 | M31: =IF($C31=0,"",E31/$C31) -> 1.1011253 | N31: =IF($C31=0,"",F31/$C31) -> 1.0812038 | O31: =IF($C31=0,"",G31/$C31) -> 1.0602099 | P31: =IF($C31=0,"",H31/$C31) -> 0.87625261 | Q31: =IF($C31=0,"",I31/$C31) -> 1.0440191
A32: 1002407 | B32: KOCH FERITLIZER ENID LLC ENID NITROGEN PLT | C32: =SUMIFS(EPA_panel!G:G,EPA_panel!A:A,$A32,EPA_panel!D:D,2017) -> 1671272.5 | D32: =SUMIFS(EPA_panel!G:G,EPA_panel!A:A,$A32,EPA_panel!D:D,2018) -> 1844749.7 | E32: =SUMIFS(EPA_panel!G:G,EPA_panel!A:A,$A32,EPA_panel!D:D,2019) -> 2203259.2 | F32: =SUMIFS(EPA_panel!G:G,EPA_panel!A:A,$A32,EPA_panel!D:D,2020) -> 2357971.3 | G32: =SUMIFS(EPA_panel!G:G,EPA_panel!A:A,$A32,EPA_panel!D:D,2021) -> 2122834.9 | H32: =SUMIFS(EPA_panel!G:G,EPA_panel!A:A,$A32,EPA_panel!D:D,2022) -> 2286677.8 | I32: =SUMIFS(EPA_panel!G:G,EPA_panel!A:A,$A32,EPA_panel!D:D,2023) -> 2378753.4 | K32: =IF($C32=0,"",C32/$C32) -> 1 | L32: =IF($C32=0,"",D32/$C32) -> 1.1037995 | M32: =IF($C32=0,"",E32/$C32) -> 1.3183124 | N32: =IF($C32=0,"",F32/$C32) -> 1.4108838 | O32: =IF($C32=0,"",G32/$C32) -> 1.2701908 | P32: =IF($C32=0,"",H32/$C32) -> 1.3682256 | Q32: =IF($C32=0,"",I32/$C32) -> 1.4233187
A33: 1002275 | B33: VERDIGRIS PLT | C33: =SUMIFS(EPA_panel!G:G,EPA_panel!A:A,$A33,EPA_panel!D:D,2017) -> 2294003.7 | D33: =SUMIFS(EPA_panel!G:G,EPA_panel!A:A,$A33,EPA_panel!D:D,2018) -> 2223728.5 | E33: =SUMIFS(EPA_panel!G:G,EPA_panel!A:A,$A33,EPA_panel!D:D,2019) -> 2075193.4 | F33: =SUMIFS(EPA_panel!G:G,EPA_panel!A:A,$A33,EPA_panel!D:D,2020) -> 2273412.5 | G33: =SUMIFS(EPA_panel!G:G,EPA_panel!A:A,$A33,EPA_panel!D:D,2021) -> 2048312.7 | H33: =SUMIFS(EPA_panel!G:G,EPA_panel!A:A,$A33,EPA_panel!D:D,2022) -> 2226326.9 | I33: =SUMIFS(EPA_panel!G:G,EPA_panel!A:A,$A33,EPA_panel!D:D,2023) -> 2106706.9 | K33: =IF($C33=0,"",C33/$C33) -> 1 | L33: =IF($C33=0,"",D33/$C33) -> 0.9693657 | M33: =IF($C33=0,"",E33/$C33) -> 0.90461641 | N33: =IF($C33=0,"",F33/$C33) -> 0.9910239 | O33: =IF($C33=0,"",G33/$C33) -> 0.8928986 | P33: =IF($C33=0,"",H33/$C33) -> 0.97049839 | Q33: =IF($C33=0,"",I33/$C33) -> 0.91835375
A34: 1004340 | B34: PCS NITROGEN FERTILIZER, L.P. | C34: =SUMIFS(EPA_panel!G:G,EPA_panel!A:A,$A34,EPA_panel!D:D,2017) -> 1210745.7 | D34: =SUMIFS(EPA_panel!G:G,EPA_panel!A:A,$A34,EPA_panel!D:D,2018) -> 1399563 | E34: =SUMIFS(EPA_panel!G:G,EPA_panel!A:A,$A34,EPA_panel!D:D,2019) -> 1402645.2 | F34: =SUMIFS(EPA_panel!G:G,EPA_panel!A:A,$A34,EPA_panel!D:D,2020) -> 1336687.9 | G34: =SUMIFS(EPA_panel!G:G,EPA_panel!A:A,$A34,EPA_panel!D:D,2021) -> 1429126.7 | H34: =SUMIFS(EPA_panel!G:G,EPA_panel!A:A,$A34,EPA_panel!D:D,2022) -> 1237900.1 | I34: =SUMIFS(EPA_panel!G:G,EPA_panel!A:A,$A34,EPA_panel!D:D,2023) -> 1508047.5 | K34: =IF($C34=0,"",C34/$C34) -> 1 | L34: =IF($C34=0,"",D34/$C34) -> 1.1559512 | M34: =IF($C34=0,"",E34/$C34) -> 1.1584969 | N34: =IF($C34=0,"",F34/$C34) -> 1.1040204 | O34: =IF($C34=0,"",G34/$C34) -> 1.180369 | P34: =IF($C34=0,"",H34/$C34) -> 1.0224278 | Q34: =IF($C34=0,"",I34/$C34) -> 1.2455526
A35: 1012918 | B35: Iowa Fertilizer Company | C35: =SUMIFS(EPA_panel!G:G,EPA_panel!A:A,$A35,EPA_panel!D:D,2017) -> 1040008.5 | D35: =SUMIFS(EPA_panel!G:G,EPA_panel!A:A,$A35,EPA_panel!D:D,2018) -> 1683195.8 | E35: =SUMIFS(EPA_panel!G:G,EPA_panel!A:A,$A35,EPA_panel!D:D,2019) -> 1705331.6 | F35: =SUMIFS(EPA_panel!G:G,EPA_panel!A:A,$A35,EPA_panel!D:D,2020) -> 1865463.6 | G35: =SUMIFS(EPA_panel!G:G,EPA_panel!A:A,$A35,EPA_panel!D:D,2021) -> 1472293.2 | H35: =SUMIFS(EPA_panel!G:G,EPA_panel!A:A,$A35,EPA_panel!D:D,2022) -> 1592712.4 | I35: =SUMIFS(EPA_panel!G:G,EPA_panel!A:A,$A35,EPA_panel!D:D,2023) -> 1349388.7 | K35: =IF($C35=0,"",C35/$C35) -> 1 | L35: =IF($C35=0,"",D35/$C35) -> 1.6184443 | M35: =IF($C35=0,"",E35/$C35) -> 1.6397285 | N35: =IF($C35=0,"",F35/$C35) -> 1.7937003 | O35: =IF($C35=0,"",G35/$C35) -> 1.415655 | P35: =IF($C35=0,"",H35/$C35) -> 1.5314417 | Q35: =IF($C35=0,"",I35/$C35) -> 1.2974785
A36: 1002229 | B36: PCS Nitrogen Ohio, L.P. | C36: =SUMIFS(EPA_panel!G:G,EPA_panel!A:A,$A36,EPA_panel!D:D,2017) -> 1253835 | D36: =SUMIFS(EPA_panel!G:G,EPA_panel!A:A,$A36,EPA_panel!D:D,2018) -> 1334389.5 | E36: =SUMIFS(EPA_panel!G:G,EPA_panel!A:A,$A36,EPA_panel!D:D,2019) -> 1336378.5 | F36: =SUMIFS(EPA_panel!G:G,EPA_panel!A:A,$A36,EPA_panel!D:D,2020) -> 1169566 | G36: =SUMIFS(EPA_panel!G:G,EPA_panel!A:A,$A36,EPA_panel!D:D,2021) -> 1383886.9 | H36: =SUMIFS(EPA_panel!G:G,EPA_panel!A:A,$A36,EPA_panel!D:D,2022) -> 1386827.2 | I36: =SUMIFS(EPA_panel!G:G,EPA_panel!A:A,$A36,EPA_panel!D:D,2023) -> 1369912 | K36: =IF($C36=0,"",C36/$C36) -> 1 | L36: =IF($C36=0,"",D36/$C36) -> 1.0642465 | M36: =IF($C36=0,"",E36/$C36) -> 1.0658328 | N36: =IF($C36=0,"",F36/$C36) -> 0.932791 | O36: =IF($C36=0,"",G36/$C36) -> 1.1037233 | P36: =IF($C36=0,"",H36/$C36) -> 1.1060683 | Q36: =IF($C36=0,"",I36/$C36) -> 1.0925776
A37: 1004183 | B37: CF Industries Nitrogen, LLC - Yazoo City Facility | C37: =SUMIFS(EPA_panel!G:G,EPA_panel!A:A,$A37,EPA_panel!D:D,2017) -> 1085674.2 | D37: =SUMIFS(EPA_panel!G:G,EPA_panel!A:A,$A37,EPA_panel!D:D,2018) -> 1109401.2 | E37: =SUMIFS(EPA_panel!G:G,EPA_panel!A:A,$A37,EPA_panel!D:D,2019) -> 1081106.4 | F37: =SUMIFS(EPA_panel!G:G,EPA_panel!A:A,$A37,EPA_panel!D:D,2020) -> 1164134.6 | G37: =SUMIFS(EPA_panel!G:G,EPA_panel!A:A,$A37,EPA_panel!D:D,2021) -> 1111678.8 | H37: =SUMIFS(EPA_panel!G:G,EPA_panel!A:A,$A37,EPA_panel!D:D,2022) -> 1131049.4 | I37: =SUMIFS(EPA_panel!G:G,EPA_panel!A:A,$A37,EPA_panel!D:D,2023) -> 1135406.3 | K37: =IF($C37=0,"",C37/$C37) -> 1 | L37: =IF($C37=0,"",D37/$C37) -> 1.0218546 | M37: =IF($C37=0,"",E37/$C37) -> 0.99579266 | N37: =IF($C37=0,"",F37/$C37) -> 1.0722688 | O37: =IF($C37=0,"",G37/$C37) -> 1.0239525 | P37: =IF($C37=0,"",H37/$C37) -> 1.0417945 | Q37: =IF($C37=0,"",I37/$C37) -> 1.0458076
A38: 1003993 | B38: EL DORADO CHEMICAL COMPANY | C38: =SUMIFS(EPA_panel!G:G,EPA_panel!A:A,$A38,EPA_panel!D:D,2017) -> 742711.2 | D38: =SUMIFS(EPA_panel!G:G,EPA_panel!A:A,$A38,EPA_panel!D:D,2018) -> 815922.5 | E38: =SUMIFS(EPA_panel!G:G,EPA_panel!A:A,$A38,EPA_panel!D:D,2019) -> 833159.1 | F38: =SUMIFS(EPA_panel!G:G,EPA_panel!A:A,$A38,EPA_panel!D:D,2020) -> 887234.3 | G38: =SUMIFS(EPA_panel!G:G,EPA_panel!A:A,$A38,EPA_panel!D:D,2021) -> 878075.9 | H38: =SUMIFS(EPA_panel!G:G,EPA_panel!A:A,$A38,EPA_panel!D:D,2022) -> 809343.1 | I38: =SUMIFS(EPA_panel!G:G,EPA_panel!A:A,$A38,EPA_panel!D:D,2023) -> 934092.2 | K38: =IF($C38=0,"",C38/$C38) -> 1 | L38: =IF($C38=0,"",D38/$C38) -> 1.098573 | M38: =IF($C38=0,"",E38/$C38) -> 1.1217807 | N38: =IF($C38=0,"",F38/$C38) -> 1.1945886 | O38: =IF($C38=0,"",G38/$C38) -> 1.1822575 | P38: =IF($C38=0,"",H38/$C38) -> 1.0897144 | Q38: =IF($C38=0,"",I38/$C38) -> 1.2576789
A39: 1003489 | B39: PCS NITROGEN FERTILIZER LP - GEISMAR AGRICULTURAL NITROGEN & PHOSPHATE PLANT | C39: =SUMIFS(EPA_panel!G:G,EPA_panel!A:A,$A39,EPA_panel!D:D,2017) -> 952816.6 | D39: =SUMIFS(EPA_panel!G:G,EPA_panel!A:A,$A39,EPA_panel!D:D,2018) -> 906539.9 | E39: =SUMIFS(EPA_panel!G:G,EPA_panel!A:A,$A39,EPA_panel!D:D,2019) -> 1054759.5 | F39: =SUMIFS(EPA_panel!G:G,EPA_panel!A:A,$A39,EPA_panel!D:D,2020) -> 1031723.3 | G39: =SUMIFS(EPA_panel!G:G,EPA_panel!A:A,$A39,EPA_panel!D:D,2021) -> 998328.3 | H39: =SUMIFS(EPA_panel!G:G,EPA_panel!A:A,$A39,EPA_panel!D:D,2022) -> 1112727.9 | I39: =SUMIFS(EPA_panel!G:G,EPA_panel!A:A,$A39,EPA_panel!D:D,2023) -> 878387.8 | K39: =IF($C39=0,"",C39/$C39) -> 1 | L39: =IF($C39=0,"",D39/$C39) -> 0.95143168 | M39: =IF($C39=0,"",E39/$C39) -> 1.1069911 | N39: =IF($C39=0,"",F39/$C39) -> 1.0828142 | O39: =IF($C39=0,"",G39/$C39) -> 1.0477654 | P39: =IF($C39=0,"",H39/$C39) -> 1.1678301 | Q39: =IF($C39=0,"",I39/$C39) -> 0.92188549
A40: 1005788 | B40: TERRA INTERNATIONAL (OKLAHOMA) LLC | C40: =SUMIFS(EPA_panel!G:G,EPA_panel!A:A,$A40,EPA_panel!D:D,2017) -> 851815.3 | D40: =SUMIFS(EPA_panel!G:G,EPA_panel!A:A,$A40,EPA_panel!D:D,2018) -> 962016.5 | E40: =SUMIFS(EPA_panel!G:G,EPA_panel!A:A,$A40,EPA_panel!D:D,2019) -> 858278.1 | F40: =SUMIFS(EPA_panel!G:G,EPA_panel!A:A,$A40,EPA_panel!D:D,2020) -> 1007327.8 | G40: =SUMIFS(EPA_panel!G:G,EPA_panel!A:A,$A40,EPA_panel!D:D,2021) -> 891795 | H40: =SUMIFS(EPA_panel!G:G,EPA_panel!A:A,$A40,EPA_panel!D:D,2022) -> 942378.3 | I40: =SUMIFS(EPA_panel!G:G,EPA_panel!A:A,$A40,EPA_panel!D:D,2023) -> 861840.5 | K40: =IF($C40=0,"",C40/$C40) -> 1 | L40: =IF($C40=0,"",D40/$C40) -> 1.1293722 | M40: =IF($C40=0,"",E40/$C40) -> 1.0075871 | N40: =IF($C40=0,"",F40/$C40) -> 1.182566 | O40: =IF($C40=0,"",G40/$C40) -> 1.0469347 | P40: =IF($C40=0,"",H40/$C40) -> 1.1063176 | Q40: =IF($C40=0,"",I40/$C40) -> 1.0117692
... A47: 1005924 | B47: Cheyenne Plant | C47: =SUMIFS(EPA_panel!G:G,EPA_panel!A:A,$A47,EPA_panel!D:D,2017) -> 320025.3 | D47: =SUMIFS(EPA_panel!G:G,EPA_panel!A:A,$A47,EPA_panel!D:D,2018) -> 384022.4 | E47: =SUMIFS(EPA_panel!G:G,EPA_panel!A:A,$A47,EPA_panel!D:D,2019) -> 380135 | F47: =SUMIFS(EPA_panel!G:G,EPA_panel!A:A,$A47,EPA_panel!D:D,2020) -> 380310.2 | G47: =SUMIFS(EPA_panel!G:G,EPA_panel!A:A,$A47,EPA_panel!D:D,2021) -> 381477 | H47: =SUMIFS(EPA_panel!G:G,EPA_panel!A:A,$A47,EPA_panel!D:D,2022) -> 382385.3 | I47: =SUMIFS(EPA_panel!G:G,EPA_panel!A:A,$A47,EPA_panel!D:D,2023) -> 318598.3 | K47: =IF($C47=0,"",C47/$C47) -> 1 | L47: =IF($C47=0,"",D47/$C47) -> 1.1999751 | M47: =IF($C47=0,"",E47/$C47) -> 1.187828 | N47: =IF($C47=0,"",F47/$C47) -> 1.1883754 | O47: =IF($C47=0,"",G47/$C47) -> 1.1920214 | P47: =IF($C47=0,"",H47/$C47) -> 1.1948596 | Q47: =IF($C47=0,"",I47/$C47) -> 0.99554098
B48: Q25 | K48: =QUARTILE(K29:K47,1) -> 1 | L48: =QUARTILE(L29:L47,1) -> 0.9651877 | M48: =QUARTILE(M29:M47,1) -> 0.97805207 | N48: =QUARTILE(N29:N47,1) -> 1.0526701 | O48: =QUARTILE(O29:O47,1) -> 0.98628694 | P48: =QUARTILE(P29:P47,1) -> 0.98779724 | Q48: =QUARTILE(Q29:Q47,1) -> 1.0036551
B49: Медиана | K49: =MEDIAN(K29:K47) -> 1 | L49: =MEDIAN(L29:L47) -> 1.0607038 | M49: =MEDIAN(M29:M47) -> 1.04983 | N49: =MEDIAN(N29:N47) -> 1.0828142 | O49: =MEDIAN(O29:O47) -> 1.0602099 | P49: =MEDIAN(P29:P47) -> 1.0897144 | Q49: =MEDIAN(Q29:Q47) -> 1.0458076
B50: Q75 | K50: =QUARTILE(K29:K47,3) -> 1 | L50: =QUARTILE(L29:L47,3) -> 1.1165858 | M50: =QUARTILE(M29:M47,3) -> 1.1143859 | N50: =QUARTILE(N29:N47,3) -> 1.1854707 | O50: =QUARTILE(O29:O47,3) -> 1.1712176 | P50: =QUARTILE(P29:P47,3) -> 1.151342 | Q50: =QUARTILE(Q29:Q47,3) -> 1.2226317
A53: N2O азотной кислоты, т CO2e
A54: Facility Id | B54: Название | C54: 2017 | D54: 2018 | E54: 2019 | F54: 2020 | G54: 2021 | H54: 2022 | I54: 2023 | K54: I 2017 | L54: I 2018 | M54: I 2019 | N54: I 2020 | O54: I 2021 | P54: I 2022 | Q54: I 2023
A55: 1002301 | B55: CF INDUSTRIES NITROGEN, LLC - DONALDSONVILLE NITROGEN COMPLEX | C55: =SUMIFS(EPA_panel!K:K,EPA_panel!A:A,$A55,EPA_panel!D:D,2017) -> 939888.42 | D55: =SUMIFS(EPA_panel!K:K,EPA_panel!A:A,$A55,EPA_panel!D:D,2018) -> 1198860 | E55: =SUMIFS(EPA_panel!K:K,EPA_panel!A:A,$A55,EPA_panel!D:D,2019) -> 1986056.2 | F55: =SUMIFS(EPA_panel!K:K,EPA_panel!A:A,$A55,EPA_panel!D:D,2020) -> 1584057.1 | G55: =SUMIFS(EPA_panel!K:K,EPA_panel!A:A,$A55,EPA_panel!D:D,2021) -> 1843039.1 | H55: =SUMIFS(EPA_panel!K:K,EPA_panel!A:A,$A55,EPA_panel!D:D,2022) -> 1325064.7 | I55: =SUMIFS(EPA_panel!K:K,EPA_panel!A:A,$A55,EPA_panel!D:D,2023) -> 1719495.2 | K55: =IF($C55=0,"",C55/$C55) -> 1 | L55: =IF($C55=0,"",D55/$C55) -> 1.2755343 | M55: =IF($C55=0,"",E55/$C55) -> 2.1130765 | N55: =IF($C55=0,"",F55/$C55) -> 1.6853672 | O55: =IF($C55=0,"",G55/$C55) -> 1.9609127 | P55: =IF($C55=0,"",H55/$C55) -> 1.4098107 | Q55: =IF($C55=0,"",I55/$C55) -> 1.8294673
A56: 1006005 | B56: CF Industries Nitrogen, LLC-Port Neal Nitrogen Complex | C56: =SUMIFS(EPA_panel!K:K,EPA_panel!A:A,$A56,EPA_panel!D:D,2017) -> 441316.25 | D56: =SUMIFS(EPA_panel!K:K,EPA_panel!A:A,$A56,EPA_panel!D:D,2018) -> 540685.24 | E56: =SUMIFS(EPA_panel!K:K,EPA_panel!A:A,$A56,EPA_panel!D:D,2019) -> 571600.65 | F56: =SUMIFS(EPA_panel!K:K,EPA_panel!A:A,$A56,EPA_panel!D:D,2020) -> 388867.65 | G56: =SUMIFS(EPA_panel!K:K,EPA_panel!A:A,$A56,EPA_panel!D:D,2021) -> 539902.39 | H56: =SUMIFS(EPA_panel!K:K,EPA_panel!A:A,$A56,EPA_panel!D:D,2022) -> 615639.39 | I56: =SUMIFS(EPA_panel!K:K,EPA_panel!A:A,$A56,EPA_panel!D:D,2023) -> 590875.59 | K56: =IF($C56=0,"",C56/$C56) -> 1 | L56: =IF($C56=0,"",D56/$C56) -> 1.225165 | M56: =IF($C56=0,"",E56/$C56) -> 1.2952178 | N56: =IF($C56=0,"",F56/$C56) -> 0.88115417 | O56: =IF($C56=0,"",G56/$C56) -> 1.2233912 | P56: =IF($C56=0,"",H56/$C56) -> 1.3950073 | Q56: =IF($C56=0,"",I56/$C56) -> 1.3388938
...

Sheet Год_эффекты
A1: Год | B1: Медиана индекса (всего) | C1: 95% ДИ н. | D1: 95% ДИ в. | E1: Медиана индекса (CO2) | F1: 95% ДИ н. | G1: 95% ДИ в. | H1: FE: всего | I1: ДИ н. | J1: ДИ в. | K1: FE: CO2 | L1: ДИ н. | M1: ДИ в. | N1: Медиана N2O | O1: ДИ н. | P1: ДИ в.
A2: 2017 | B2: 1 | C2: 1 | D2: 1 | E2: 1 | F2: 1 | G2: 1 | H2: 1 | I2: 1 | J2: 1 | K2: 1 | L2: 1 | M2: 1 | N2: 1 | O2: 1 | P2: 1
A3: 2018 | B3: 1.0194241 | C3: 0.98373988 | D3: 1.103811 | E3: 1.0607038 | F3: 0.9693657 | G3: 1.1037995 | H3: 1.045918 | I3: 0.98050861 | J3: 1.1218437 | K3: 1.0692429 | L3: 1.0105618 | M3: 1.1438691 | N3: 1.1109327 | O3: 0.74636245 | P3: 1.225165
A4: 2019 | B4: 0.99558194 | C4: 0.94941556 | D4: 1.0898658 | E4: 1.04983 | F4: 0.99579266 | G4: 1.1069911 | H4: 1.0364049 | I4: 0.97233916 | J4: 1.1131431 | K4: 1.0725082 | L4: 1.0150874 | M4: 1.1453325 | N4: 0.83897582 | O4: 0.6495671 | P4: 1.2847748
A5: 2020 | B5: 1.0569833 | C5: 0.97037986 | D5: 1.1057507 | E5: 1.0828142 | F5: 1.0662193 | G5: 1.182566 | H5: 1.0900239 | I5: 1.0097156 | J5: 1.190687 | K5: 1.1304811 | L5: 1.0660925 | M5: 1.2122957 | N5: 0.92628924 | O5: 0.78862454 | P5: 1.579978
A6: 2021 | B6: 1.0442247 | C6: 0.95835954 | D6: 1.1359157 | E6: 1.0602099 | F6: 1.0239525 | G6: 1.1620661 | H6: 1.0352727 | I6: 0.96410342 | J6: 1.1117517 | K6: 1.068515 | L6: 1.0144334 | M6: 1.1294461 | N6: 1.037537 | O6: 0.71944013 | P6: 1.3605536
A7: 2022 | B7: 1.0486631 | C7: 1.0015151 | D7: 1.141583 | E7: 1.0897144 | F7: 1.0050961 | G7: 1.1348539 | H7: 1.0638012 | I7: 0.97177176 | J7: 1.1600995 | K7: 1.0864727 | L7: 1.0320097 | M7: 1.1522075 | N7: 1.1533474 | O7: 0.87802474 | P7: 1.4440869
A8: 2023 | B8: 1.0281023 | C8: 0.99529283 | D8: 1.1564066 | E8: 1.0458076 | F8: 1.0117692 | G8: 1.1997107 | H8: 1.0889755 | I8: 1.0034835 | J8: 1.1879407 | K8: 1.1030057 | L8: 1.0439257 | M8: 1.1653884 | N8: 0.96096265 | O8: 0.74417167 | P8: 1.6744186
A10: Значения рассчитаны скриптом analyze.py (бутстреп по заводам, 2000 повторов, seed 2026). FE — exp(γ_t) из модели ln E_it = α_i + γ_t + ε_it на сбалансированной панели, γ_2017 = 0.

Sheet CF_мощности
A1: Facility Id | B1: Комплекс | C1: Мощность NH3, тыс. кор. т (10-K 2022) | D1: Мощность, тыс. т | E1: Всего 2022, т CO2e | F1: CO2 2022, т | G1: N2O 2022, т CO2e | H1: Процесс G 2022, т | I1: Сжигание 2022, т | J1: CO2 на т мощности | K1: Процесс на т мощности | L1: Сжигание на т мощности | M1: N2O на т мощности | N1: Всего на т мощности
A2: 1002301 | B2: Donaldsonville | C2: 4335 | D2: =C2*0.90718474 -> 3932.6458 | E2: =SUMIFS(EPA_panel!F:F,EPA_panel!A:A,A2,EPA_panel!D:D,2022) -> 9155496.1 | F2: =SUMIFS(EPA_panel!G:G,EPA_panel!A:A,A2,EPA_panel!D:D,2022) -> 7827402 | G2: =SUMIFS(EPA_panel!H:H,EPA_panel!A:A,A2,EPA_panel!D:D,2022) -> 1326712.1 | H2: =SUMIFS(EPA_panel!J:J,EPA_panel!A:A,A2,EPA_panel!D:D,2022) -> 4894258.6 | I2: =SUMIFS(EPA_panel!I:I,EPA_panel!A:A,A2,EPA_panel!D:D,2022) -> 2936172.7 | J2: =F2/(D2*1000) -> 1.9903653 | K2: =H2/(D2*1000) -> 1.2445206 | L2: =I2/(D2*1000) -> 0.74661509 | M2: =G2/(D2*1000) -> 0.33735865 | N2: =E2/(D2*1000) -> 2.3280754
A3: 1006005 | B3: Port Neal | C3: 1230 | D3: =C3*0.90718474 -> 1115.8372 | E3: =SUMIFS(EPA_panel!F:F,EPA_panel!A:A,A3,EPA_panel!D:D,2022) -> 3180457.4 | F3: =SUMIFS(EPA_panel!G:G,EPA_panel!A:A,A3,EPA_panel!D:D,2022) -> 2563756 | G3: =SUMIFS(EPA_panel!H:H,EPA_panel!A:A,A3,EPA_panel!D:D,2022) -> 616216.92 | H3: =SUMIFS(EPA_panel!J:J,EPA_panel!A:A,A3,EPA_panel!D:D,2022) -> 1626175.4 | I3: =SUMIFS(EPA_panel!I:I,EPA_panel!A:A,A3,EPA_panel!D:D,2022) -> 938642.62 | J3: =F3/(D3*1000) -> 2.2976075 | K3: =H3/(D3*1000) -> 1.457359 | L3: =I3/(D3*1000) -> 0.84120031 | M3: =G3/(D3*1000) -> 0.55224624 | N3: =E3/(D3*1000) -> 2.850288
A4: 1002275 | B4: Verdigris | C4: 1210 | D4: =C4*0.90718474 -> 1097.6935 | E4: =SUMIFS(EPA_panel!F:F,EPA_panel!A:A,A4,EPA_panel!D:D,2022) -> 3698601.7 | F4: =SUMIFS(EPA_panel!G:G,EPA_panel!A:A,A4,EPA_panel!D:D,2022) -> 2226326.9 | G4: =SUMIFS(EPA_panel!H:H,EPA_panel!A:A,A4,EPA_panel!D:D,2022) -> 1471825.3 | H4: =SUMIFS(EPA_panel!J:J,EPA_panel!A:A,A4,EPA_panel!D:D,2022) -> 1272276.9 | I4: =SUMIFS(EPA_panel!I:I,EPA_panel!A:A,A4,EPA_panel!D:D,2022) -> 955035.3 | J4: =F4/(D4*1000) -> 2.0281862 | K4: =H4/(D4*1000) -> 1.1590456 | L4: =I4/(D4*1000) -> 0.8700382 | M4: =G4/(D4*1000) -> 1.3408344 | N4: =E4/(D4*1000) -> 3.3694301
A5: 1005788 | B5: Woodward (Terra OK) | C5: 480 | D5: =C5*0.90718474 -> 435.44868 | E5: =SUMIFS(EPA_panel!F:F,EPA_panel!A:A,A5,EPA_panel!D:D,2022) -> 1303743.3 | F5: =SUMIFS(EPA_panel!G:G,EPA_panel!A:A,A5,EPA_panel!D:D,2022) -> 942378.3 | G5: =SUMIFS(EPA_panel!H:H,EPA_panel!A:A,A5,EPA_panel!D:D,2022) -> 361180.77 | H5: =SUMIFS(EPA_panel!J:J,EPA_panel!A:A,A5,EPA_panel!D:D,2022) -> 551356.8 | I5: =SUMIFS(EPA_panel!I:I,EPA_panel!A:A,A5,EPA_panel!D:D,2022) -> 391425.38 | J5: =F5/(D5*1000) -> 2.1641547 | K5: =H5/(D5*1000) -> 1.2661809 | L5: =I5/(D5*1000) -> 0.89890129 | M5: =G5/(D5*1000) -> 0.8294451 | N5: =E5/(D5*1000) -> 2.9940229
A6: 1004183 | B6: Yazoo City | C6: 570 | D6: =C6*0.90718474 -> 517.0953 | E6: =SUMIFS(EPA_panel!F:F,EPA_panel!A:A,A6,EPA_panel!D:D,2022) -> 2454971 | F6: =SUMIFS(EPA_panel!G:G,EPA_panel!A:A,A6,EPA_panel!D:D,2022) -> 1131049.4 | G6: =SUMIFS(EPA_panel!H:H,EPA_panel!A:A,A6,EPA_panel!D:D,2022) -> 1323697.8 | H6: =SUMIFS(EPA_panel!J:J,EPA_panel!A:A,A6,EPA_panel!D:D,2022) -> 656263.3 | I6: =SUMIFS(EPA_panel!I:I,EPA_panel!A:A,A6,EPA_panel!D:D,2022) -> 475276.56 | J6: =F6/(D6*1000) -> 2.1873132 | K6: =H6/(D6*1000) -> 1.2691341 | L6: =I6/(D6*1000) -> 0.91912759 | M6: =G6/(D6*1000) -> 2.5598721 | N6: =E6/(D6*1000) -> 4.747618
B8: Минимум | J8: =MIN(J2:J6) -> 1.9903653 | K8: =MIN(K2:K6) -> 1.1590456 | L8: =MIN(L2:L6) -> 0.74661509 | M8: =MIN(M2:M6) -> 0.33735865 | N8: =MIN(N2:N6) -> 2.3280754
B9: Медиана | J9: =MEDIAN(J2:J6) -> 2.1641547 | K9: =MEDIAN(K2:K6) -> 1.2661809 | L9: =MEDIAN(L2:L6) -> 0.8700382 | M9: =MEDIAN(M2:M6) -> 0.8294451 | N9: =MEDIAN(N2:N6) -> 2.9940229
B10: Максимум | J10: =MAX(J2:J6) -> 2.2976075 | K10: =MAX(K2:K6) -> 1.457359 | L10: =MAX(L2:L6) -> 0.91912759 | M10: =MAX(M2:M6) -> 2.5598721 | N10: =MAX(N2:N6) -> 4.747618
A12: Мощность: CF Industries, Form 10-K FY2022, таблица производственных мощностей (короткие тонны, с учётом нормальных простоев). 1 кор. т = 0,90718474 т.

Sheet Калибровка_CT
A1: Завод | B1: Climate TRACE v6, т CO2e/год (модель) | C1: Измерено, т CO2e | D1: Год измерения | E1: Измерено / модель | F1: Источник измерения
A2: Donaldsonville | B2: 5663868 | C2: =SUMIFS(EPA_panel!F:F,EPA_panel!A:A,1002301,EPA_panel!D:D,2023) -> 9475265.7 | D2: 2023 | E2: =C2/B2 -> 1.672932 | F2: EPA GHGRP
A3: Port Neal | B3: 1152173 | C3: =SUMIFS(EPA_panel!F:F,EPA_panel!A:A,1006005,EPA_panel!D:D,2023) -> 3191236.6 | D3: 2023 | E3: =C3/B3 -> 2.7697547 | F3: EPA GHGRP
A4: Verdigris | B4: 1437192 | C4: =SUMIFS(EPA_panel!F:F,EPA_panel!A:A,1002275,EPA_panel!D:D,2023) -> 3354662.5 | D4: 2023 | E4: =C4/B4 -> 2.3341784 | F4: EPA GHGRP
A5: Woodward (Terra OK) | B5: 1440217 | C5: =SUMIFS(EPA_panel!F:F,EPA_panel!A:A,1005788,EPA_panel!D:D,2023) -> 1190499.6 | D5: 2023 | E5: =C5/B5 -> 0.8266113 | F5: EPA GHGRP
A6: Yara Sluiskil | B6: 2626178 | C6: 2750148 | D6: 2023 | E6: =C6/B6 -> 1.0472055 | F6: EU ETS (EUTL) по IndustryAtlas; в PBL то же значение отнесено к 2022 г.
A8: Минимум | E8: =MIN(E2:E6) -> 0.8266113
A9: Медиана | E9: =MEDIAN(E2:E6) -> 1.672932
A10: Максимум | E10: =MAX(E2:E6) -> 2.7697547
A12: Невинномысский Азот, модель Climate TRACE | B12: 1444447
A13: Азот: модель × медиана отношения | C13: =B12*E9 -> 2416461.5
A14: Азот: диапазон (мин.–макс. отношения) | C14: =B12*E8 -> 1193996.2 | D14: =B12*E10 -> 4000763.8
A16: Модельные оценки Climate TRACE по IndustryAtlas (снимок 23.06.2026). Вывод: для интегрированных азотных комплексов модель занижает выбросы до 2,8 раза; как самостоятельная оценка уровня «Азота» непригодна, используется только для проверки.

Sheet Sluiskil_EU
A1: Год | B1: EU ETS, тыс. т CO2e | C1: Индекс к 2017 | D1: PRTR CO2, тыс. т | E1: PRTR N2O, тыс. т CO2e
A2: 2017 | B2: 3828 | C2: =B2/$B$2 -> 1 | D2: 3580 | E2: 245
A3: 2018 | B3: 3607 | C3: =B3/$B$2 -> 0.9422675 | D3: 3350 | E3: 253
A4: 2019 | B4: 3447 | C4: =B4/$B$2 -> 0.90047022 | D4: 3170 | E4: 259
A5: 2020 | B5: 3298 | C5: =B5/$B$2 -> 0.8615465 | D5: 3130 | E5: 155
A6: 2021 | B6: 3190 | C6: =B6/$B$2 -> 0.83333333 | D6: 3050 | E6: 158
A7: 2022 | B7: 2750 | C7: =B7/$B$2 -> 0.7183908
A9: Источник: Lamboo S. (PBL/TNO), Update Report: Decarbonisation options for the Dutch fertiliser industry, 2024, табл. 3–4. Мощность по аммиаку 1,9 млн т/год.

Sheet Азот_оценка
A1: Ввод
A2: Мощность по аммиаку, тыс. т/год — сценарий «низкий» | B2: 1000
A3: Мощность по аммиаку, тыс. т/год — сценарий «базовый» | B3: 1160
A4: Мощность по аммиаку, тыс. т/год — сценарий «высокий» | B4: 1350
A5: Мощность не подтверждена первичным документом: 1 160 — сайт предприятия по своду; 1 350 — ИТС/сторонний справочник; 1 000 — оценка в СМИ. Заменить данными годового отчёта (e-disclosure.ru).
A7: Удельные параметры аналогов
A8: CO2 на т мощности: мин / медиана / макс | B8: =CF_мощности!J8 -> 1.9903653 | C8: =CF_мощности!J9 -> 2.1641547 | D8: =CF_мощности!J10 -> 2.2976075
A9: Процессный CO2 на т мощности (медиана) | C9: =CF_мощности!K9 -> 1.2661809
A10: N2O / процессный CO2: Q25 / медиана / Q75 | B10: =Аналоги!D22 -> 0.10218515 | C10: =Аналоги!D23 -> 0.35361085 | D10: =Аналоги!D24 -> 0.60832454
A12: Уровень 2023 г., тыс. т (базовая мощность)
A13: Компонент | B13: Нижняя граница | C13: Центральная | D13: Верхняя граница
A14: CO2 | B14: =$B$3*B8 -> 2308.8238 | C14: =$B$3*C8 -> 2510.4195 | D14: =$B$3*D8 -> 2665.2247
A15: N2O (в CO2e) | B15: =$B$3*$C$9*B10 -> 150.08647 | C15: =$B$3*$C$9*C10 -> 519.37296 | D15: =$B$3*$C$9*D10 -> 893.48874
A16: Всего | B16: =B14+B15 -> 2458.9103 | C16: =C14+C15 -> 3029.7924 | D16: =D14+D15 -> 3558.7135
A17: Чистый процессный CO2 (поток для обмена), тыс. т | C17: =$B$3*C9 -> 1468.7699
A18: Действующий сбыт пищевой CO2, тыс. т (EuroChem, 2018) | C18: 32
A19: Доля действующего сбыта в процессном CO2 | C19: =C18/C17 -> 0.02178694
A20: Отношение к оценке Climate TRACE (1 444 тыс. т) | C20: =C16/1444.447 -> 2.0975449
A22: Ряд 2017–2023, тыс. т CO2e (центральная мощность; динамика — годовые эффекты FE по аналогам США)
A23: Год | B23: Индекс FE (всего) | C23: Оценка «Азота» | D23: 95% ДИ н. (динамика) | E23: 95% ДИ в. (динамика) | F23: Низкая мощность | G23: Высокая мощность
A24: 2017 | B24: =Год_эффекты!H2 -> 1 | C24: =$C$16*B24/Год_эффекты!$H$8 -> 2782.2412 | D24: =$C$16*Год_эффекты!I2/Год_эффекты!$H$8 -> 2782.2412 | E24: =$C$16*Год_эффекты!J2/Год_эффекты!$H$8 -> 2782.2412 | F24: =C24*$B$2/$B$3 -> 2398.4838 | G24: =C24*$B$4/$B$3 -> 3237.9532
A25: 2018 | B25: =Год_эффекты!H3 -> 1.045918 | C25: =$C$16*B25/Год_эффекты!$H$8 -> 2909.9963 | D25: =$C$16*Год_эффекты!I3/Год_эффекты!$H$8 -> 2728.0115 | E25: =$C$16*Год_эффекты!J3/Год_эффекты!$H$8 -> 3121.2397 | F25: =C25*$B$2/$B$3 -> 2508.6175 | G25: =C25*$B$4/$B$3 -> 3386.6336
A26: 2019 | B26: =Год_эффекты!H4 -> 1.0364049 | C26: =$C$16*B26/Год_эффекты!$H$8 -> 2883.5284 | D26: =$C$16*Год_эффекты!I4/Год_эффекты!$H$8 -> 2705.2821 | E26: =$C$16*Год_эффекты!J4/Год_эффекты!$H$8 -> 3097.0326 | F26: =C26*$B$2/$B$3 -> 2485.8003 | G26: =C26*$B$4/$B$3 -> 3355.8304
A27: 2020 | B27: =Год_эффекты!H5 -> 1.0900239 | C27: =$C$16*B27/Год_эффекты!$H$8 -> 3032.7096 | D27: =$C$16*Год_эффекты!I5/Год_эффекты!$H$8 -> 2809.2724 | E27: =$C$16*Год_эффекты!J5/Год_эффекты!$H$8 -> 3312.7785 | F27: =C27*$B$2/$B$3 -> 2614.4048 | G27: =C27*$B$4/$B$3 -> 3529.4465
A28: 2021 | B28: =Год_эффекты!H6 -> 1.0352727 | C28: =$C$16*B28/Год_эффекты!$H$8 -> 2880.3784 | D28: =$C$16*Год_эффекты!I6/Год_эффекты!$H$8 -> 2682.3683 | E28: =$C$16*Год_эффекты!J6/Год_эффекты!$H$8 -> 3093.1615 | F28: =C28*$B$2/$B$3 -> 2483.0848 | G28: =C28*$B$4/$B$3 -> 3352.1645
A29: 2022 | B29: =Год_эффекты!H7 -> 1.0638012 | C29: =$C$16*B29/Год_эффекты!$H$8 -> 2959.7516 | D29: =$C$16*Год_эффекты!I7/Год_эффекты!$H$8 -> 2703.7035 | E29: =$C$16*Год_эффекты!J7/Год_эффекты!$H$8 -> 3227.6766 | F29: =C29*$B$2/$B$3 -> 2551.51 | G29: =C29*$B$4/$B$3 -> 3444.5385
A30: 2023 | B30: =Год_эффекты!H8 -> 1.0889755 | C30: =$C$16*B30/Год_эффекты!$H$8 -> 3029.7924 | D30: =$C$16*Год_эффекты!I8/Год_эффекты!$H$8 -> 2791.9331 | E30: =$C$16*Год_эффекты!J8/Год_эффекты!$H$8 -> 3305.1376 | F30: =C30*$B$2/$B$3 -> 2611.89 | G30: =C30*$B$4/$B$3 -> 3526.0515
A32: Ряд привязан к уровню 2023 г. и восстанавливается назад по годовым эффектам; интервал отражает только неопределённость динамики. Неопределённость уровня — строки 14–16 и сценарии мощности.
